//wrapper for the controller to handle the error using next();
const asyncWrapper = (fn) => {
  return async (req, res, next) => {
    try {
      await fn(req, res, next);
    } catch (error) {
      next(error);
    }
  };
};

module.exports = asyncWrapper;
